<?xml version="1.0" encoding="UTF-8"?>
<!-- Generated by org.testng.reporters.JUnitReportReporter -->
<testsuite hostname="VinnchenkoLI" name="com.example.tests.ContactCreationTests" tests="5" failures="0" timestamp="24 Mar 2014 11:49:04 GMT" time="17.898" errors="5">
  <testcase name="testContactCreationWithValidData" time="3.430" classname="com.example.tests.ContactCreationTests">
    <error type="java.lang.AssertionError" message="Lists differ at element [0]: ContactData [name=, lastname=, address=test1179771943, phone1=test-1517348536, phone3=test1801590259, mail1=, mail2=test-1970097808] != ContactData [name= , lastname= , address= , phone1= , phone3=null, mail1=null, mail2=null] expected [ContactData [name=, lastname=, address=test1179771943, phone1=test-1517348536, phone3=test1801590259, mail1=, mail2=test-1970097808]] but found [ContactData [name= , lastname= , address= , phone1= , phone3=null, mail1=null, mail2=null]]">
      <![CDATA[java.lang.AssertionError: Lists differ at element [0]: ContactData [name=, lastname=, address=test1179771943, phone1=test-1517348536, phone3=test1801590259, mail1=, mail2=test-1970097808] != ContactData [name= , lastname= , address= , phone1= , phone3=null, mail1=null, mail2=null] expected [ContactData [name=, lastname=, address=test1179771943, phone1=test-1517348536, phone3=test1801590259, mail1=, mail2=test-1970097808]] but found [ContactData [name= , lastname= , address= , phone1= , phone3=null, mail1=null, mail2=null]]
	at org.testng.Assert.fail(Assert.java:94)
	at org.testng.Assert.failNotEquals(Assert.java:494)
	at org.testng.Assert.assertEquals(Assert.java:123)
	at org.testng.Assert.assertEquals(Assert.java:549)
	at org.testng.Assert.assertEquals(Assert.java:514)
	at com.example.tests.ContactCreationTests.testContactCreationWithValidData(ContactCreationTests.java:36)
	at sun.reflect.NativeMethodAccessorImpl.invoke0(Native Method)
	at sun.reflect.NativeMethodAccessorImpl.invoke(Unknown Source)
	at sun.reflect.DelegatingMethodAccessorImpl.invoke(Unknown Source)
	at java.lang.reflect.Method.invoke(Unknown Source)
	at org.testng.internal.MethodInvocationHelper.invokeMethod(MethodInvocationHelper.java:84)
	at org.testng.internal.Invoker.invokeMethod(Invoker.java:714)
	at org.testng.internal.Invoker.invokeTestMethod(Invoker.java:901)
	at org.testng.internal.Invoker.invokeTestMethods(Invoker.java:1231)
	at org.testng.internal.TestMethodWorker.invokeTestMethods(TestMethodWorker.java:127)
	at org.testng.internal.TestMethodWorker.run(TestMethodWorker.java:111)
	at org.testng.TestRunner.privateRun(TestRunner.java:767)
	at org.testng.TestRunner.run(TestRunner.java:617)
	at org.testng.SuiteRunner.runTest(SuiteRunner.java:334)
	at org.testng.SuiteRunner.runSequentially(SuiteRunner.java:329)
	at org.testng.SuiteRunner.privateRun(SuiteRunner.java:291)
	at org.testng.SuiteRunner.run(SuiteRunner.java:240)
	at org.testng.SuiteRunnerWorker.runSuite(SuiteRunnerWorker.java:52)
	at org.testng.SuiteRunnerWorker.run(SuiteRunnerWorker.java:86)
	at org.testng.TestNG.runSuitesSequentially(TestNG.java:1224)
	at org.testng.TestNG.runSuitesLocally(TestNG.java:1149)
	at org.testng.TestNG.run(TestNG.java:1057)
	at org.testng.remote.RemoteTestNG.run(RemoteTestNG.java:111)
	at org.testng.remote.RemoteTestNG.initAndRun(RemoteTestNG.java:204)
	at org.testng.remote.RemoteTestNG.main(RemoteTestNG.java:175)
]]>
    </error>
  </testcase> <!-- testContactCreationWithValidData -->
  <testcase name="testContactCreationWithValidData" time="3.543" classname="com.example.tests.ContactCreationTests">
    <error type="java.lang.AssertionError" message="Lists differ at element [4]: ContactData [name= test-1015749464, lastname= test-1015749464, address= test-1015749464, phone1= test-1015749464, phone3=null, mail1=null, mail2=null] != ContactData [name=test-1235142713 , lastname=test-1235142713 , address=test-1235142713 , phone1=test-1235142713 , phone3=null, mail1=null, mail2=null] expected [ContactData [name= test-1015749464, lastname= test-1015749464, address= test-1015749464, phone1= test-1015749464, phone3=null, mail1=null, mail2=null]] but found [ContactData [name=test-1235142713 , lastname=test-1235142713 , address=test-1235142713 , phone1=test-1235142713 , phone3=null, mail1=null, mail2=null]]">
      <![CDATA[java.lang.AssertionError: Lists differ at element [4]: ContactData [name= test-1015749464, lastname= test-1015749464, address= test-1015749464, phone1= test-1015749464, phone3=null, mail1=null, mail2=null] != ContactData [name=test-1235142713 , lastname=test-1235142713 , address=test-1235142713 , phone1=test-1235142713 , phone3=null, mail1=null, mail2=null] expected [ContactData [name= test-1015749464, lastname= test-1015749464, address= test-1015749464, phone1= test-1015749464, phone3=null, mail1=null, mail2=null]] but found [ContactData [name=test-1235142713 , lastname=test-1235142713 , address=test-1235142713 , phone1=test-1235142713 , phone3=null, mail1=null, mail2=null]]
	at org.testng.Assert.fail(Assert.java:94)
	at org.testng.Assert.failNotEquals(Assert.java:494)
	at org.testng.Assert.assertEquals(Assert.java:123)
	at org.testng.Assert.assertEquals(Assert.java:549)
	at org.testng.Assert.assertEquals(Assert.java:514)
	at com.example.tests.ContactCreationTests.testContactCreationWithValidData(ContactCreationTests.java:36)
	at sun.reflect.NativeMethodAccessorImpl.invoke0(Native Method)
	at sun.reflect.NativeMethodAccessorImpl.invoke(Unknown Source)
	at sun.reflect.DelegatingMethodAccessorImpl.invoke(Unknown Source)
	at java.lang.reflect.Method.invoke(Unknown Source)
	at org.testng.internal.MethodInvocationHelper.invokeMethod(MethodInvocationHelper.java:84)
	at org.testng.internal.Invoker.invokeMethod(Invoker.java:714)
	at org.testng.internal.Invoker.invokeTestMethod(Invoker.java:901)
	at org.testng.internal.Invoker.invokeTestMethods(Invoker.java:1231)
	at org.testng.internal.TestMethodWorker.invokeTestMethods(TestMethodWorker.java:127)
	at org.testng.internal.TestMethodWorker.run(TestMethodWorker.java:111)
	at org.testng.TestRunner.privateRun(TestRunner.java:767)
	at org.testng.TestRunner.run(TestRunner.java:617)
	at org.testng.SuiteRunner.runTest(SuiteRunner.java:334)
	at org.testng.SuiteRunner.runSequentially(SuiteRunner.java:329)
	at org.testng.SuiteRunner.privateRun(SuiteRunner.java:291)
	at org.testng.SuiteRunner.run(SuiteRunner.java:240)
	at org.testng.SuiteRunnerWorker.runSuite(SuiteRunnerWorker.java:52)
	at org.testng.SuiteRunnerWorker.run(SuiteRunnerWorker.java:86)
	at org.testng.TestNG.runSuitesSequentially(TestNG.java:1224)
	at org.testng.TestNG.runSuitesLocally(TestNG.java:1149)
	at org.testng.TestNG.run(TestNG.java:1057)
	at org.testng.remote.RemoteTestNG.run(RemoteTestNG.java:111)
	at org.testng.remote.RemoteTestNG.initAndRun(RemoteTestNG.java:204)
	at org.testng.remote.RemoteTestNG.main(RemoteTestNG.java:175)
]]>
    </error>
  </testcase> <!-- testContactCreationWithValidData -->
  <testcase name="testContactCreationWithValidData" time="3.291" classname="com.example.tests.ContactCreationTests">
    <error type="java.lang.AssertionError" message="Lists differ at element [0]: ContactData [name=test-1235142713, lastname=, address=, phone1=test-68749095, phone3=, mail1=test-157232567, mail2=] != ContactData [name= , lastname= , address= , phone1= , phone3=null, mail1=null, mail2=null] expected [ContactData [name=test-1235142713, lastname=, address=, phone1=test-68749095, phone3=, mail1=test-157232567, mail2=]] but found [ContactData [name= , lastname= , address= , phone1= , phone3=null, mail1=null, mail2=null]]">
      <![CDATA[java.lang.AssertionError: Lists differ at element [0]: ContactData [name=test-1235142713, lastname=, address=, phone1=test-68749095, phone3=, mail1=test-157232567, mail2=] != ContactData [name= , lastname= , address= , phone1= , phone3=null, mail1=null, mail2=null] expected [ContactData [name=test-1235142713, lastname=, address=, phone1=test-68749095, phone3=, mail1=test-157232567, mail2=]] but found [ContactData [name= , lastname= , address= , phone1= , phone3=null, mail1=null, mail2=null]]
	at org.testng.Assert.fail(Assert.java:94)
	at org.testng.Assert.failNotEquals(Assert.java:494)
	at org.testng.Assert.assertEquals(Assert.java:123)
	at org.testng.Assert.assertEquals(Assert.java:549)
	at org.testng.Assert.assertEquals(Assert.java:514)
	at com.example.tests.ContactCreationTests.testContactCreationWithValidData(ContactCreationTests.java:36)
	at sun.reflect.NativeMethodAccessorImpl.invoke0(Native Method)
	at sun.reflect.NativeMethodAccessorImpl.invoke(Unknown Source)
	at sun.reflect.DelegatingMethodAccessorImpl.invoke(Unknown Source)
	at java.lang.reflect.Method.invoke(Unknown Source)
	at org.testng.internal.MethodInvocationHelper.invokeMethod(MethodInvocationHelper.java:84)
	at org.testng.internal.Invoker.invokeMethod(Invoker.java:714)
	at org.testng.internal.Invoker.invokeTestMethod(Invoker.java:901)
	at org.testng.internal.Invoker.invokeTestMethods(Invoker.java:1231)
	at org.testng.internal.TestMethodWorker.invokeTestMethods(TestMethodWorker.java:127)
	at org.testng.internal.TestMethodWorker.run(TestMethodWorker.java:111)
	at org.testng.TestRunner.privateRun(TestRunner.java:767)
	at org.testng.TestRunner.run(TestRunner.java:617)
	at org.testng.SuiteRunner.runTest(SuiteRunner.java:334)
	at org.testng.SuiteRunner.runSequentially(SuiteRunner.java:329)
	at org.testng.SuiteRunner.privateRun(SuiteRunner.java:291)
	at org.testng.SuiteRunner.run(SuiteRunner.java:240)
	at org.testng.SuiteRunnerWorker.runSuite(SuiteRunnerWorker.java:52)
	at org.testng.SuiteRunnerWorker.run(SuiteRunnerWorker.java:86)
	at org.testng.TestNG.runSuitesSequentially(TestNG.java:1224)
	at org.testng.TestNG.runSuitesLocally(TestNG.java:1149)
	at org.testng.TestNG.run(TestNG.java:1057)
	at org.testng.remote.RemoteTestNG.run(RemoteTestNG.java:111)
	at org.testng.remote.RemoteTestNG.initAndRun(RemoteTestNG.java:204)
	at org.testng.remote.RemoteTestNG.main(RemoteTestNG.java:175)
]]>
    </error>
  </testcase> <!-- testContactCreationWithValidData -->
  <testcase name="testContactCreationWithValidData" time="4.134" classname="com.example.tests.ContactCreationTests">
    <error type="java.lang.AssertionError" message="Lists differ at element [3]: ContactData [name= test-1015749464, lastname= test-1015749464, address= test-1015749464, phone1= test-1015749464, phone3=null, mail1=null, mail2=null] != ContactData [name=test-1462979425 , lastname=test-1462979425 , address=test-1462979425 , phone1=test-1462979425 , phone3=null, mail1=null, mail2=null] expected [ContactData [name= test-1015749464, lastname= test-1015749464, address= test-1015749464, phone1= test-1015749464, phone3=null, mail1=null, mail2=null]] but found [ContactData [name=test-1462979425 , lastname=test-1462979425 , address=test-1462979425 , phone1=test-1462979425 , phone3=null, mail1=null, mail2=null]]">
      <![CDATA[java.lang.AssertionError: Lists differ at element [3]: ContactData [name= test-1015749464, lastname= test-1015749464, address= test-1015749464, phone1= test-1015749464, phone3=null, mail1=null, mail2=null] != ContactData [name=test-1462979425 , lastname=test-1462979425 , address=test-1462979425 , phone1=test-1462979425 , phone3=null, mail1=null, mail2=null] expected [ContactData [name= test-1015749464, lastname= test-1015749464, address= test-1015749464, phone1= test-1015749464, phone3=null, mail1=null, mail2=null]] but found [ContactData [name=test-1462979425 , lastname=test-1462979425 , address=test-1462979425 , phone1=test-1462979425 , phone3=null, mail1=null, mail2=null]]
	at org.testng.Assert.fail(Assert.java:94)
	at org.testng.Assert.failNotEquals(Assert.java:494)
	at org.testng.Assert.assertEquals(Assert.java:123)
	at org.testng.Assert.assertEquals(Assert.java:549)
	at org.testng.Assert.assertEquals(Assert.java:514)
	at com.example.tests.ContactCreationTests.testContactCreationWithValidData(ContactCreationTests.java:36)
	at sun.reflect.NativeMethodAccessorImpl.invoke0(Native Method)
	at sun.reflect.NativeMethodAccessorImpl.invoke(Unknown Source)
	at sun.reflect.DelegatingMethodAccessorImpl.invoke(Unknown Source)
	at java.lang.reflect.Method.invoke(Unknown Source)
	at org.testng.internal.MethodInvocationHelper.invokeMethod(MethodInvocationHelper.java:84)
	at org.testng.internal.Invoker.invokeMethod(Invoker.java:714)
	at org.testng.internal.Invoker.invokeTestMethod(Invoker.java:901)
	at org.testng.internal.Invoker.invokeTestMethods(Invoker.java:1231)
	at org.testng.internal.TestMethodWorker.invokeTestMethods(TestMethodWorker.java:127)
	at org.testng.internal.TestMethodWorker.run(TestMethodWorker.java:111)
	at org.testng.TestRunner.privateRun(TestRunner.java:767)
	at org.testng.TestRunner.run(TestRunner.java:617)
	at org.testng.SuiteRunner.runTest(SuiteRunner.java:334)
	at org.testng.SuiteRunner.runSequentially(SuiteRunner.java:329)
	at org.testng.SuiteRunner.privateRun(SuiteRunner.java:291)
	at org.testng.SuiteRunner.run(SuiteRunner.java:240)
	at org.testng.SuiteRunnerWorker.runSuite(SuiteRunnerWorker.java:52)
	at org.testng.SuiteRunnerWorker.run(SuiteRunnerWorker.java:86)
	at org.testng.TestNG.runSuitesSequentially(TestNG.java:1224)
	at org.testng.TestNG.runSuitesLocally(TestNG.java:1149)
	at org.testng.TestNG.run(TestNG.java:1057)
	at org.testng.remote.RemoteTestNG.run(RemoteTestNG.java:111)
	at org.testng.remote.RemoteTestNG.initAndRun(RemoteTestNG.java:204)
	at org.testng.remote.RemoteTestNG.main(RemoteTestNG.java:175)
]]>
    </error>
  </testcase> <!-- testContactCreationWithValidData -->
  <testcase name="testContactCreationWithValidData" time="3.500" classname="com.example.tests.ContactCreationTests">
    <error type="java.lang.AssertionError" message="Lists differ at element [3]: ContactData [name= test-1015749464, lastname= test-1015749464, address= test-1015749464, phone1= test-1015749464, phone3=null, mail1=null, mail2=null] != ContactData [name=test-1235142713 , lastname=test-1235142713 , address=test-1235142713 , phone1=test-1235142713 , phone3=null, mail1=null, mail2=null] expected [ContactData [name= test-1015749464, lastname= test-1015749464, address= test-1015749464, phone1= test-1015749464, phone3=null, mail1=null, mail2=null]] but found [ContactData [name=test-1235142713 , lastname=test-1235142713 , address=test-1235142713 , phone1=test-1235142713 , phone3=null, mail1=null, mail2=null]]">
      <![CDATA[java.lang.AssertionError: Lists differ at element [3]: ContactData [name= test-1015749464, lastname= test-1015749464, address= test-1015749464, phone1= test-1015749464, phone3=null, mail1=null, mail2=null] != ContactData [name=test-1235142713 , lastname=test-1235142713 , address=test-1235142713 , phone1=test-1235142713 , phone3=null, mail1=null, mail2=null] expected [ContactData [name= test-1015749464, lastname= test-1015749464, address= test-1015749464, phone1= test-1015749464, phone3=null, mail1=null, mail2=null]] but found [ContactData [name=test-1235142713 , lastname=test-1235142713 , address=test-1235142713 , phone1=test-1235142713 , phone3=null, mail1=null, mail2=null]]
	at org.testng.Assert.fail(Assert.java:94)
	at org.testng.Assert.failNotEquals(Assert.java:494)
	at org.testng.Assert.assertEquals(Assert.java:123)
	at org.testng.Assert.assertEquals(Assert.java:549)
	at org.testng.Assert.assertEquals(Assert.java:514)
	at com.example.tests.ContactCreationTests.testContactCreationWithValidData(ContactCreationTests.java:36)
	at sun.reflect.NativeMethodAccessorImpl.invoke0(Native Method)
	at sun.reflect.NativeMethodAccessorImpl.invoke(Unknown Source)
	at sun.reflect.DelegatingMethodAccessorImpl.invoke(Unknown Source)
	at java.lang.reflect.Method.invoke(Unknown Source)
	at org.testng.internal.MethodInvocationHelper.invokeMethod(MethodInvocationHelper.java:84)
	at org.testng.internal.Invoker.invokeMethod(Invoker.java:714)
	at org.testng.internal.Invoker.invokeTestMethod(Invoker.java:901)
	at org.testng.internal.Invoker.invokeTestMethods(Invoker.java:1231)
	at org.testng.internal.TestMethodWorker.invokeTestMethods(TestMethodWorker.java:127)
	at org.testng.internal.TestMethodWorker.run(TestMethodWorker.java:111)
	at org.testng.TestRunner.privateRun(TestRunner.java:767)
	at org.testng.TestRunner.run(TestRunner.java:617)
	at org.testng.SuiteRunner.runTest(SuiteRunner.java:334)
	at org.testng.SuiteRunner.runSequentially(SuiteRunner.java:329)
	at org.testng.SuiteRunner.privateRun(SuiteRunner.java:291)
	at org.testng.SuiteRunner.run(SuiteRunner.java:240)
	at org.testng.SuiteRunnerWorker.runSuite(SuiteRunnerWorker.java:52)
	at org.testng.SuiteRunnerWorker.run(SuiteRunnerWorker.java:86)
	at org.testng.TestNG.runSuitesSequentially(TestNG.java:1224)
	at org.testng.TestNG.runSuitesLocally(TestNG.java:1149)
	at org.testng.TestNG.run(TestNG.java:1057)
	at org.testng.remote.RemoteTestNG.run(RemoteTestNG.java:111)
	at org.testng.remote.RemoteTestNG.initAndRun(RemoteTestNG.java:204)
	at org.testng.remote.RemoteTestNG.main(RemoteTestNG.java:175)
]]>
    </error>
  </testcase> <!-- testContactCreationWithValidData -->
</testsuite> <!-- com.example.tests.ContactCreationTests -->
